<?xml version="1.0" ?>
<robot name="box" version="1.0">
  <link name="box">
    <inertial>
      <origin xyz="0.0 0.0 -0.034677907824516296" rpy="0.0 -0.0 0.0"/>
      <mass value="2.789491653442383"/>
      <inertia ixx="0.08964705467224121" ixy="0.0" ixz="0.0" iyy="0.08021242171525955" iyz="0.0" izz="0.07528116554021835"/>
    </inertial>
    <collision name="Geom_3">
      <origin xyz="0.0 0.1575 -0.0025" rpy="0.0 -0.0 0.0"/>
      <geometry>
        <box size="0.340312 0.005 0.335"/>
      </geometry>
    </collision>
    <collision name="Geom_2">
      <origin xyz="-0.167578 0.0 -0.0025" rpy="0.0 -0.0 0.0"/>
      <geometry>
        <box size="0.005156 0.32 0.335"/>
      </geometry>
    </collision>
    <collision name="Geom_4">
      <origin xyz="0.0 -0.1575 -0.0025" rpy="0.0 -0.0 0.0"/>
      <geometry>
        <box size="0.340312 0.005 0.335"/>
      </geometry>
    </collision>
    <collision name="Geom_0">
      <origin xyz="0.0 0.0 -0.1675" rpy="0.0 -0.0 0.0"/>
      <geometry>
        <box size="0.34 0.32 0.005"/>
      </geometry>
    </collision>
    <collision name="Geom_1">
      <origin xyz="0.167578 0.0 -0.0025" rpy="0.0 -0.0 0.0"/>
      <geometry>
        <box size="0.005156 0.32 0.335"/>
      </geometry>
    </collision>
  </link>
  <joint name="box_flap_side_1_joint" type="revolute">
    <origin xyz="0.17000000178813934 0.0 0.16599999368190765" rpy="0.0 -0.0 0.0"/>
    <axis xyz="0 1 0"/>
    <parent link="box"/>
    <child link="box_flap_side_1"/>
    <limit effort="1000" lower="-3.14" upper="3.14" velocity="1000"/>
  </joint>
  <link name="box_flap_side_1">
    <inertial>
      <origin xyz="-0.17000000178813934 -1.5240807504923737e-09 -3.309754914582186e-09" rpy="0.0 -0.0 0.0"/>
      <mass value="0.2165265679359436"/>
      <inertia ixx="0.003919629380106926" ixy="0.0" ixz="0.0" iyy="0.0020787641406059265" iyz="0.0" izz="0.0018410093616694212"/>
    </inertial>
    <collision name="BoxFlapSide1">
      <origin xyz="-0.1700000072951671 -1.5240807574521301e-09 -3.3097549890378998e-09" rpy="-3.141592653589793 -1.5707963267948961 0.0"/>
      <geometry>
        <mesh filename="package://articulated_objects/box/urdf/box/stl/BoxFlapSide1.stl" scale="1.0000000000000002 -0.9999999999999996 0.9999999999999998"/>
      </geometry>
    </collision>
  </link>
  <joint name="box_flap_side_2_joint" type="revolute">
    <origin xyz="-0.17000000178813934 0.0 0.1679999977350235" rpy="0.0 -0.0 0.0"/>
    <axis xyz="0 -1 0"/>
    <parent link="box"/>
    <child link="box_flap_side_2"/>
    <limit effort="1000" lower="-3.14" upper="3.14" velocity="1000"/>
  </joint>
  <link name="box_flap_side_2">
    <inertial>
      <origin xyz="0.17000001668930054 -3.853585228696943e-10 -1.7394633910344792e-12" rpy="0.0 -0.0 0.0"/>
      <mass value="0.2165265679359436"/>
      <inertia ixx="0.003919629380106926" ixy="0.0" ixz="0.0" iyy="0.002078763674944639" iyz="0.0" izz="0.0018410093616694212"/>
    </inertial>
    <collision name="BoxFlapSide2">
      <origin xyz="0.17000000947241017 -3.853585327311238e-10 -1.7394634132564953e-12" rpy="-3.141592653589793 -1.5707963267948961 0.0"/>
      <geometry>
        <mesh filename="package://articulated_objects/box/urdf/box/stl/BoxFlapSide2.stl" scale="1.0000000000000002 -0.9999999999999996 0.9999999999999998"/>
      </geometry>
    </collision>
  </link>
</robot>